Workbook

Sheet NEW_summary_order_items_rows
A1: order_number | B1: order_date | C1: product | D1: asin | E1: sku | F1: units | G1: refunds | H1: sales | I1: promo | J1: sellable_quota | K1: refund_cost | L1: amazon_fees | M1: cost_of_goods | N1: shipping | O1: gross_profit | P1: expenses | Q1: net_profit | R1: margin | S1: roi | T1: coupon | U1: row_type | V1: updated_at
A2: 111-1013291-1045011 | B2: 46176 | C2: Musemory 60 Positive Cards Turtle Jar, Affirmation Cards For Women, Friendship Gift, Best Friend Gift, Positive Decor, Sea Turtle Gifts, Card Turtle for Her, Decoration For Home Office | D2: B0F9PGKBX2 | E2: POSITIVEJAR_TURTLE | F2: 1 | G2: 0 | H2: 13.99 | I2: 0.00 | K2: 0.00 | L2: 0.00 | M2: -1.20 | N2: 0.00 | O2: 12.79 | P2: 0.00 | Q2: 12.79 | R2: 91.42 | S2: 1065.83 | T2: 0.00 | U2: normal | V2: 2026-06-11 09:59:52.156572+00
A3: 111-1292153-4599429 | B3: 46176 | C3: 50 Positive Messages in Bottle,Anxiety Relief Items, Stress Relief, Self Care Kit for Mediation,Positive Affirmation Gifts for Women, Self Care Kit for Mediation, Unique Health and Wellness Gifts | D3: B0CSJZLTP5 | E3: LY-IU2S-D65B | F3: 1 | G3: 0 | H3: 15.98 | I3: 0.00 | K3: 0.00 | L3: 0.00 | M3: -1.00 | N3: 0.00 | O3: 14.98 | P3: 0.00 | Q3: 14.98 | R3: 93.74 | S3: 1498.00 | T3: 0.00 | U3: normal | V3: 2026-06-11 09:59:52.156572+00
A4: 111-2123246-7694605 | B4: 46176 | C4: Dad Hat, Best Dad Ever Flag Hat, Fathers Day Birthday Gift for Papa from Daughter Son, Trucker Hat for Men, Gift for Dad | D4: B0GWRC6XR9 | E4: FATHERDAY_DADHAT | F4: 1 | G4: 0 | H4: 15.98 | I4: 0.00 | K4: 0.00 | L4: 0.00 | M4: 0.00 | N4: 0.00 | O4: 15.98 | P4: 0.00 | Q4: 15.98 | R4: 100.00 | T4: 0.00 | U4: normal | V4: 2026-06-11 09:59:52.156572+00
A5: 111-2348073-4114606 | B5: 46176 | C5: Friendship Elephant Ornament with Story Card, Gifts for Women, Friendship Birthday Gifts for Women, Birthday Presents for Best Friends Sisters Special Bond Decor (Sunflower Elephant) | D5: B0FDQCBNZW | E5: ONM_ELEPHANT_02 | F5: 1 | G5: 0 | H5: 6.99 | I5: 0.00 | K5: 0.00 | L5: 0.00 | M5: 0.00 | N5: 0.00 | O5: 6.99 | P5: 0.00 | Q5: 6.99 | R5: 100.00 | T5: 0.00 | U5: normal | V5: 2026-06-11 09:59:52.156572+00
A6: 111-3498099-5675433 | B6: 46176 | C6: Magnetic Acrylic Car Visor Photo Clip, Father's Day, Birthday Gift For Dad, Picture Holder with Love Message, Drive Safe Car Accessory For Dad, Best Dad Ever Gifts, Birthday Gifts from Daughter | D6: B0F8VBSG3T | E6: CARVISOR_DAD | F6: 1 | G6: 0 | H6: 9.98 | I6: 0.00 | K6: 0.00 | L6: 0.00 | M6: 0.00 | N6: 0.00 | O6: 9.98 | P6: 0.00 | Q6: 9.98 | R6: 100.00 | T6: 0.00 | U6: normal | V6: 2026-06-11 09:59:52.156572+00
A7: 111-4976673-9831434 | B7: 46176 | C7: Scratch Off Map of United States, All 63 US National Parks Scratch Off Poster, Scratch Off World Map, Travel Scratch Off Map, Us Map for Travel Tracking, Valentine Gift, Valentine Gifts For Her, Valentine Gift For Men [Unknown Binding] [1905] | D7: B0DJR4343W | E7: PU-2DN9-R32Y | F7: 1 | G7: 0 | H7: 17.89 | I7: 0.00 | K7: 0.00 | L7: 0.00 | M7: 0.00 | N7: 0.00 | O7: 17.89 | P7: 0.00 | Q7: 17.89 | R7: 100.00 | T7: 0.00 | U7: normal | V7: 2026-06-11 09:59:52.156572+00
A8: 111-5871499-1533841 | B8: 46176 | C8: 250th Anniversary Decorations for Home, Patriotic Eagle Door Sign, America 250th Birthday Decor, Fourth of July Decorations, USA Independence Day Hanging Wall Decor, Patriotic Decorations | D8: B0GZGMLGDD | E8: 250TH_DOORSIGN_DAIBANG | F8: 1 | G8: 0 | H8: 10.98 | I8: 0.00 | K8: 0.00 | L8: 0.00 | M8: 0.00 | N8: 0.00 | O8: 10.98 | P8: 0.00 | Q8: 10.98 | R8: 100.00 | T8: 0.00 | U8: normal | V8: 2026-06-11 09:59:52.156572+00
A9: 111-5883462-6720216 | B9: 46176 | C9: Nursing 2026 Graduation Gift, Nurse Gifts for Women, Nursing Ornament, Appreciation Gifts for Women, New Nurse Gift, Gifts for Nurses | D9: B0F62HNF16 | E9: ONM_NURSE | F9: 1 | G9: 0 | H9: 9.98 | I9: 0.00 | K9: 0.00 | L9: 0.00 | M9: 0.00 | N9: 0.00 | O9: 9.98 | P9: 0.00 | Q9: 9.98 | R9: 100.00 | T9: 0.00 | U9: normal | V9: 2026-06-11 09:59:52.156572+00
A10: 111-6002479-2648245 | B10: 46176 | C10: Musemory Magnetic Reward Jar, 9" DIY Name 40+ Tokens Star Face Magnetic Reward Jar Gifts for Classroom, Classroom Management Tool, Reward Jars for Kids Magnetic, Back to School Gift for Kids | D10: B0FBM5TDLH | E10: REWARDJAR_STAR | F10: 1 | G10: 0 | H10: 21.98 | I10: 0.00 | K10: 0.00 | L10: 0.00 | M10: -3.00 | N10: 0.00 | O10: 18.98 | P10: 0.00 | Q10: 18.98 | R10: 86.35 | S10: 632.67 | T10: 0.00 | U10: normal | V10: 2026-06-11 09:59:52.156572+00
A11: 111-8486162-9769063 | B11: 46176 | C11: Dad Hat, Best Dad Ever Flag Hat, Fathers Day Birthday Gift for Papa from Daughter Son, Trucker Hat for Men, Gift for Dad | D11: B0GWRC6XR9 | E11: FATHERDAY_DADHAT | F11: 1 | G11: 0 | H11: 15.98 | I11: 0.00 | K11: 0.00 | L11: 0.00 | M11: 0.00 | N11: 0.00 | O11: 15.98 | P11: 0.00 | Q11: 15.98 | R11: 100.00 | T11: 0.00 | U11: normal | V11: 2026-06-11 09:59:52.156572+00
A12: 111-9439137-1446627 | B12: 46176 | C12: Read Me When Bible Verse Jar, Bible Accessories, Prayer Jar, Graduation for Her, Christian Gift For Women, Teacher Gifts, Fathers Day Gift For Dad (Bible Jar for Daughter) | D12: B0F7RL4G2Q | E12: bible jar_daughter | F12: 1 | G12: 0 | H12: 11.99 | I12: 0.00 | K12: 0.00 | L12: 0.00 | M12: 0.00 | N12: 0.00 | O12: 11.99 | P12: 0.00 | Q12: 11.99 | R12: 100.00 | T12: 0.00 | U12: normal | V12: 2026-06-11 09:59:52.156572+00
A13: 111-9970460-8529829 | B13: 46176 | C13: Funny Nurse Badge Reel Retractable ID Holder - Cute Duck Nurse Badge Clip for RN CNA LPN, Medical ID Badge Holder for Scrubs, Gift Idea (Stick) | D13: B0GVYXMMNX | E13: NURSEBADGEREEL_STICKEM | F13: 1 | G13: 0 | H13: 7.98 | I13: 0.00 | K13: 0.00 | L13: 0.00 | M13: 0.00 | N13: 0.00 | O13: 7.98 | P13: 0.00 | Q13: 7.98 | R13: 100.00 | T13: 0.00 | U13: normal | V13: 2026-06-11 09:59:52.156572+00
A14: 112-0413892-2476221 | B14: 46176 | C14: 250th Anniversary Decorations for Home, Patriotic Eagle Door Sign, America 250th Birthday Decor, Fourth of July Decorations, USA Independence Day Hanging Wall Decor, Patriotic Decorations | D14: B0GZGMLGDD | E14: 250TH_DOORSIGN_DAIBANG | F14: 1 | G14: 0 | H14: 10.98 | I14: 0.00 | K14: 0.00 | L14: 0.00 | M14: 0.00 | N14: 0.00 | O14: 10.98 | P14: 0.00 | Q14: 10.98 | R14: 100.00 | T14: 0.00 | U14: normal | V14: 2026-06-11 09:59:52.156572+00
A15: 112-0714318-1746612 | B15: 46176 | C15: 250th Anniversary USA Ornament 1776 -2026, America 250 Eagle Patriotic Tabletop Decoration, 4th of JulyDecorations, Patriotic Gift for Veterans Independence Day | D15: B0GVYTQLYB | E15: DESK-DECOR_AMERICA250 | F15: 1 | G15: 0 | H15: 14.98 | I15: 0.00 | K15: 0.00 | L15: 0.00 | M15: 0.00 | N15: 0.00 | O15: 14.98 | P15: 0.00 | Q15: 14.98 | R15: 100.00 | T15: 0.00 | U15: normal | V15: 2026-06-11 09:59:52.156572+00
A16: 112-1859494-0931441 | B16: 46176 | C16: Musemory 60 Positive Sunshine Cards Jar, Sunshine Gifts, Affirmation Cards Sunshine For Women, Friendship Gift, Positive Decor, Key Chain Sunshine | D16: B0F9PFJ2C9 | E16: POSITIVEJAR_CLOUDSUN | F16: 1 | G16: 0 | H16: 12.99 | I16: 0.00 | K16: 0.00 | L16: 0.00 | M16: -1.50 | N16: 0.00 | O16: 11.49 | P16: 0.00 | Q16: 11.49 | R16: 88.45 | S16: 766.00 | T16: 0.00 | U16: normal | V16: 2026-06-11 09:59:52.156572+00
A17: 112-1905962-6865832 | B17: 46176 | C17: First Day Last Day of School Board Sign for Kids, First Day of Daycare Sign, Back To School Board Sign, Forst Day of School Sign, First Day of School Board - Back to School Kids Supplies Preschool | D17: B0FDWNP259 | E17: SCHOOLBOARD_02 | F17: 1 | G17: 0 | H17: 15.98 | I17: 0.00 | K17: 0.00 | L17: 0.00 | M17: 0.00 | N17: 0.00 | O17: 15.98 | P17: 0.00 | Q17: 15.98 | R17: 100.00 | T17: 0.00 | U17: normal | V17: 2026-06-11 09:59:52.156572+00
A18: 112-3344212-9529028 | B18: 46176 | C18: Musemory 60 Positive Sunshine Cards Jar, Sunshine Gifts, Affirmation Cards Sunshine For Women, Friendship Gift, Positive Decor, Key Chain Sunshine | D18: B0F9PFJ2C9 | E18: POSITIVEJAR_CLOUDSUN | F18: 1 | G18: 0 | H18: 12.99 | I18: 0.00 | K18: 0.00 | L18: 0.00 | M18: -1.50 | N18: 0.00 | O18: 11.49 | P18: 0.00 | Q18: 11.49 | R18: 88.45 | S18: 766.00 | T18: 0.00 | U18: normal | V18: 2026-06-11 09:59:52.156572+00
A19: 112-3699085-5697846 | B19: 46176 | C19: Bible Verse Jar, Christian Gifts for Women, Inspirational Scriptures for Women, Daughters, Bible Accessories, Mothers Day gifts for Mom, Decorative Glass Inspirational Scripture Jar | D19: B0D3PR4S5B | E19: bile jar-02 | F19: 1 | G19: 0 | H19: 15.99 | I19: 0.00 | K19: 0.00 | L19: 0.00 | M19: 0.00 | N19: 0.00 | O19: 15.99 | P19: 0.00 | Q19: 15.99 | R19: 100.00 | T19: 0.00 | U19: normal | V19: 2026-06-11 09:59:52.156572+00
A20: 112-3971093-5175431 | B20: 46176 | E20: ONM_NURSE | F20: 0 | G20: 1 | H20: 0.00 | I20: 0.00 | K20: -8.66 | L20: 0.00 | M20: 0.00 | N20: 0.00 | O20: -8.66 | P20: 0.00 | Q20: -8.66 | T20: 0.00 | U20: return | V20: 2026-06-11 09:59:52.156572+00
A21: 112-5467204-8750611 | B21: 46176 | C21: 2 PCS Resist Vinyl Sticker Decal, Statue of Liberty New York Vinyl Sticker Decal - 5'' Laptop, Car, Bumper, Travel Luggage Sticker, Resist Sticker | D21: B0F2T9B1Y2 | E21: CS-S8XU-RCDA | F21: 1 | G21: 0 | H21: 5.89 | I21: 0.00 | K21: 0.00 | L21: 0.00 | M21: 0.00 | N21: 0.00 | O21: 5.89 | P21: 0.00 | Q21: 5.89 | R21: 100.00 | T21: 0.00 | U21: normal | V21: 2026-06-11 09:59:52.156572+00
A22: 112-5873300-7991404 | B22: 46176 | C22: Musemory Magnetic Reward Jar, Personalized Smiley Tokens Reward Jar for Kids, DIY, Reward Jar, Classroom Management Tool, Reward Jars for Kids Magnetic, Back to School Gift for Kids | D22: B0F5V9Z11R | E22: UY-AO7W-2FWB | F22: 1 | G22: 0 | H22: 15.98 | I22: 0.00 | K22: 0.00 | L22: 0.00 | M22: -3.00 | N22: 0.00 | O22: 12.98 | P22: 0.00 | Q22: 12.98 | R22: 81.23 | S22: 432.67 | T22: 0.00 | U22: normal | V22: 2026-06-11 09:59:52.156572+00
A23: 112-6274610-6221005 | B23: 46176 | C23: Funny Card for Dad from Daughter, Son, Kids on Fathers Day - Heartfelt Message to Father, Perfect for Birthday, Father's Day, Humorous Dad Greeting Cards, Gifts for Dad (Eyes Closed TV Watching) | D23: B0F8VM1HS2 | E23: Y3-9FHG-0UWD | F23: 1 | G23: 0 | H23: 5.99 | I23: 0.00 | K23: 0.00 | L23: 0.00 | M23: 0.00 | N23: 0.00 | O23: 5.99 | P23: 0.00 | Q23: 5.99 | R23: 100.00 | T23: 0.00 | U23: normal | V23: 2026-06-11 09:59:52.156572+00
A24: 112-6793310-9839468 | B24: 46176 | C24: Musemory 60 Positive Cards Turtle Jar, Affirmation Cards For Women, Friendship Gift, Best Friend Gift, Positive Decor, Sea Turtle Gifts, Card Turtle for Her, Decoration For Home Office | D24: B0F9PGKBX2 | E24: POSITIVEJAR_TURTLE | F24: 1 | G24: 0 | H24: 13.99 | I24: 0.00 | K24: 0.00 | L24: 0.00 | M24: -1.20 | N24: 0.00 | O24: 12.79 | P24: 0.00 | Q24: 12.79 | R24: 91.42 | S24: 1065.83 | T24: 0.00 | U24: normal | V24: 2026-06-11 09:59:52.156572+00
A25: 112-7077440-9483408 | B25: 46176 | C25: 250th Anniversary Decorations for Home, Patriotic Eagle Door Sign, America 250th Birthday Decor, Fourth of July Decorations, USA Independence Day Hanging Wall Decor, Patriotic Decorations | D25: B0GZGMLGDD | E25: 250TH_DOORSIGN_DAIBANG | F25: 1 | G25: 0 | H25: 10.98 | I25: 0.00 | K25: 0.00 | L25: 0.00 | M25: 0.00 | N25: 0.00 | O25: 10.98 | P25: 0.00 | Q25: 10.98 | R25: 100.00 | T25: 0.00 | U25: normal | V25: 2026-06-11 09:59:52.156572+00
A26: 112-7789653-2173044 | B26: 46176 | C26: Dad Joke Jar, Gifts Set with Card Hat, Gag Gift for Men, Joke Cards Jar, Fathers Day Gift, Birthday Present for Husband, Fun Family Game Night Humor Kit | D26: B0GWQF4FM6 | E26: FATHERDAY_DADJOKESJAR | F26: 1 | G26: 0 | H26: 7.98 | I26: 0.00 | K26: 0.00 | L26: 0.00 | M26: 0.00 | N26: 0.00 | O26: 7.98 | P26: 0.00 | Q26: 7.98 | R26: 100.00 | T26: 0.00 | U26: normal | V26: 2026-06-11 09:59:52.156572+00
A27: 112-8699877-2660231 | B27: 46176 | C27: 250th Anniversary USA Ornament 1776 -2026, America 250 Eagle Patriotic Tabletop Decoration, 4th of JulyDecorations, Patriotic Gift for Veterans Independence Day | D27: B0GVYTQLYB | E27: DESK-DECOR_AMERICA250 | F27: 1 | G27: 0 | H27: 14.98 | I27: 0.00 | K27: 0.00 | L27: 0.00 | M27: 0.00 | N27: 0.00 | O27: 14.98 | P27: 0.00 | Q27: 14.98 | R27: 100.00 | T27: 0.00 | U27: normal | V27: 2026-06-11 09:59:52.156572+00
A28: 113-1546338-7769832 | B28: 46176 | C28: Positive Affirmations Jar, Positive Affirmation Cards for Women, Unique for Women, Birthday Gifts for Women, Affirmation Cards for Men, Valentines day Gifts | D28: B0F1Y83S8W | E28: WT-NW9C-FZDB | F28: 1 | G28: 0 | H28: 7.98 | I28: 0.00 | K28: 0.00 | L28: 0.00 | M28: -1.00 | N28: 0.00 | O28: 6.98 | P28: 0.00 | Q28: 6.98 | R28: 87.47 | S28: 698.00 | T28: 0.00 | U28: normal | V28: 2026-06-11 09:59:52.156572+00
A29: 113-2124536-6044202 | B29: 46176 | E29: 250TH_DOORSIGN_250THANNIVERSARY | F29: 0 | G29: 1 | H29: 0.00 | I29: 0.00 | K29: -11.27 | L29: 0.00 | M29: 0.00 | N29: 0.00 | O29: -11.27 | P29: 0.00 | Q29: -11.27 | T29: 0.00 | U29: return | V29: 2026-06-11 09:59:52.156572+00
A30: 113-2732469-4371414 | B30: 46176 | C30: 250th Anniversary Decorations for Home, Patriotic Door Sign, America 250th Birthday Decor, Fourth of July Decorations, USA 1776-2026 Hanging Wall Plaque, Patriotic Decorations for Front Door | D30: B0GZHBKGCM | E30: 250TH_DOORSIGN_250THANNIVERSARY | F30: 1 | G30: 0 | H30: 12.99 | I30: 0.00 | K30: 0.00 | L30: 0.00 | M30: 0.00 | N30: 0.00 | O30: 12.99 | P30: 0.00 | Q30: 12.99 | R30: 100.00 | T30: 0.00 | U30: normal | V30: 2026-06-11 09:59:52.156572+00
A31: 113-3236592-9629018 | B31: 46176 | C31: Musemory Magnetic Reward Jar, Personalized Smiley Tokens Reward Jar for Kids, DIY, Reward Jar, Classroom Management Tool, Reward Jars for Kids Magnetic, Back to School Gift for Kids | D31: B0F5V9Z11R | E31: UY-AO7W-2FWB | F31: 1 | G31: 0 | H31: 15.98 | I31: 0.00 | K31: 0.00 | L31: 0.00 | M31: -3.00 | N31: 0.00 | O31: 12.98 | P31: 0.00 | Q31: 12.98 | R31: 81.23 | S31: 432.67 | T31: 0.00 | U31: normal | V31: 2026-06-11 09:59:52.156572+00
A32: 113-3599387-5974614 | B32: 46176 | C32: Reasons Why I Love You Mom Jar, DIY Love Notes in a Jar with Envelopes, What I Love About Mom, Mothers Day Gifts for Mom from Daughter Son, Mother Birthday Gifts | D32: B0GSDQ2CQ6 | E32: MOTHERDAY_ILOVEYOUMOM | F32: 1 | G32: 0 | H32: 13.98 | I32: 0.00 | K32: 0.00 | L32: 0.00 | M32: -2.50 | N32: 0.00 | O32: 11.48 | P32: 0.00 | Q32: 11.48 | R32: 82.12 | S32: 459.20 | T32: 0.00 | U32: normal | V32: 2026-06-11 09:59:52.156572+00
A33: 113-4845767-1605832 | B33: 46176 | C33: Musemory Magnetic Reward Jar, Personalized Smiley Tokens Reward Jar for Kids, DIY, Reward Jar, Classroom Management Tool, Reward Jars for Kids Magnetic, Back to School Gift for Kids | D33: B0F5V9Z11R | E33: UY-AO7W-2FWB | F33: 1 | G33: 0 | H33: 15.98 | I33: 0.00 | K33: 0.00 | L33: 0.00 | M33: -3.00 | N33: 0.00 | O33: 12.98 | P33: 0.00 | Q33: 12.98 | R33: 81.23 | S33: 432.67 | T33: 0.00 | U33: normal | V33: 2026-06-11 09:59:52.156572+00
A34: 113-5174170-4848260 | B34: 46176 | C34: Positive Baseball Affirmation Jar - 60 Motivational Messages for Players, Sports Lovers, Cute Baseball Gift for Kids, Teens, Athletes | Encouragement Jar, Gifts for Teen Boy | D34: B0FXGWJZL4 | E34: POSITIVEJAR_BASEBALL | F34: 1 | G34: 0 | H34: 11.99 | I34: 0.00 | K34: 0.00 | L34: 0.00 | M34: 0.00 | N34: 0.00 | O34: 11.99 | P34: 0.00 | Q34: 11.99 | R34: 100.00 | T34: 0.00 | U34: normal | V34: 2026-06-11 09:59:52.156572+00
A35: 113-6802263-2738611 | B35: 46176 | C35: Badass Affirmation Jar, Inspirational Gift, Daily Affirmations for Women, Funny Affirmation Cards, Birthday Gifts for Her, Women, Valentines Day Gifts | D35: B0DM93RNKC | E35: bible jar_03 | F35: 1 | G35: 0 | H35: 11.99 | I35: 0.00 | K35: 0.00 | L35: 0.00 | M35: -1.50 | N35: 0.00 | O35: 10.49 | P35: 0.00 | Q35: 10.49 | R35: 87.49 | S35: 699.33 | T35: 0.00 | U35: normal | V35: 2026-06-11 09:59:52.156572+00
A36: 113-7145139-3375448 | B36: 46176 | C36: Bible Verse Jar, Christian Gifts for Women, Inspirational Scriptures for Women, Daughters, Bible Accessories, Mothers Day gifts for Mom, Decorative Glass Inspirational Scripture Jar | D36: B0D3PR4S5B | E36: bile jar-02 | F36: 1 | G36: 0 | H36: 15.99 | I36: 0.00 | K36: 0.00 | L36: 0.00 | M36: 0.00 | N36: 0.00 | O36: 15.99 | P36: 0.00 | Q36: 15.99 | R36: 100.00 | T36: 0.00 | U36: normal | V36: 2026-06-11 09:59:52.156572+00
A37: 113-9785006-5172245 | B37: 46176 | C37: Romantic Wedding Gift for Couple, Wooden Heart Tree Tabletop Decor with "Our Adventure Begins", Wedding Gift for Husband Wife, Engagement Bridal Shower Newlywed Home Decor | D37: B0H1LJX4T9 | E37: WEDDING_DEVOM_OURADVENTUREBEGIN | F37: 1 | G37: 0 | H37: 9.99 | I37: 0.00 | K37: 0.00 | L37: 0.00 | M37: 0.00 | N37: 0.00 | O37: 9.99 | P37: 0.00 | Q37: 9.99 | R37: 100.00 | T37: 0.00 | U37: normal | V37: 2026-06-11 09:59:52.156572+00
A38: 114-0050202-1860221 | B38: 46176 | C38: Best Dad Ever American Flag Hat, Best Dad Ever Gifts, Meaningful Gift for Dad from Daughter Son, Leather Patch Trucker Cap, Dad Hats | D38: B0GY4JSS94 | E38: FATHERDAY_BESTDADEVERHAT | F38: 1 | G38: 0 | H38: 17.98 | I38: 0.00 | K38: 0.00 | L38: 0.00 | M38: 0.00 | N38: 0.00 | O38: 17.98 | P38: 0.00 | Q38: 17.98 | R38: 100.00 | T38: 0.00 | U38: normal | V38: 2026-06-11 09:59:52.156572+00
A39: 114-0485677-9289868 | B39: 46176 | C39: America 250 Patriotic Gnome Decor, USA 250th Anniversary Decoration 1776-2026, Independence Day Wooden Tabletop Sign, Liberty Bell & We The People Gnome Display, Patriotic Home Office Shelf Decor | D39: B0H2LZQHTH | E39: 250TH_GNOME_AMERICA250 | F39: 1 | G39: 0 | H39: 9.99 | I39: 0.00 | K39: 0.00 | L39: 0.00 | M39: 0.00 | N39: 0.00 | O39: 9.99 | P39: 0.00 | Q39: 9.99 | R39: 100.00 | T39: 0.00 | U39: normal | V39: 2026-06-11 09:59:52.156572+00
A40: 114-0703451-4349053 | B40: 46176 | C40: Musemory 60 Positive Cards Turtle Jar, Affirmation Cards For Women, Friendship Gift, Best Friend Gift, Positive Decor, Sea Turtle Gifts, Card Turtle for Her, Decoration For Home Office | D40: B0F9PGKBX2 | E40: POSITIVEJAR_TURTLE | F40: 1 | G40: 0 | H40: 13.99 | I40: 0.00 | K40: 0.00 | L40: 0.00 | M40: -1.20 | N40: 0.00 | O40: 12.79 | P40: 0.00 | Q40: 12.79 | R40: 91.42 | S40: 1065.83 | T40: 0.00 | U40: normal | V40: 2026-06-11 09:59:52.156572+00
...

Sheet DrHai_Craft_Order_Items
A1: Order number | B1: Order date | C1: Product | D1: ASIN | E1: SKU | F1: Units | G1: Refunds | H1: Sales | I1: Promo | J1: Sellable Quota | K1: Refund сost | L1: Amazon fees | M1: Cost of Goods | N1: Shipping | O1: Gross profit | P1: Expenses | Q1: Net profit | R1: Margin | S1: ROI | T1: Coupon | U1: Comment
A2: 114-0703451-4349053 / Shipped / COG: 1.2 / FBA | B2: 46176 | C2: Musemory 60 Positive Cards Turtle Jar, Affirmation Cards For Women, Friendship Gift, Best Friend Gift, Positive Decor, Sea Turtle Gifts, Card Turtle for Her, Decoration For Home Office / Price: 13.99 | D2: B0F9PGKBX2 | E2: POSITIVEJAR_TURTLE | F2: 1 | H2: 13.99 | L2: -6.17 | M2: -1.2 | O2: 6.62 | Q2: 6.62 | R2: 47.32 | S2: 551.67
A3: 111-2123246-7694605 / Shipped / COG: 0 / FBA | B3: 46176 | C3: Dad Hat, Best Dad Ever Flag Hat, Fathers Day Birthday Gift for Papa from Daughter Son, Trucker Hat for Men, Gift for Dad / Price: 15.98 | D3: B0GWRC6XR9 | E3: FATHERDAY_DADHAT | F3: 1 | H3: 15.98 | L3: -6.43 | O3: 9.55 | Q3: 9.55 | R3: 59.76
A4: 114-2565360-6033006 / Shipped / COG: 0 / FBA | B4: 46176 | C4: Funny Nurse Badge Reel Retractable ID Holder – Cute Duck Nurse Badge Clip for RN CNA LPN, Medical ID Badge Holder for Scrubs, Gift Idea (Cuff) / Price: 7.98 | D4: B0GVZ1733Q | E4: NURSEBADGEREEL_CUFFEM | F4: 1 | H4: 7.98 | L4: -1.32 | O4: 6.66 | Q4: 6.66 | R4: 83.46
A5: 112-7077440-9483408 / Shipped / COG: 0 / FBA | B5: 46176 | C5: 250th Anniversary Decorations for Home, Patriotic Eagle Door Sign, America 250th Birthday Decor, Fourth of July Decorations, USA Independence Day Hanging Wall Decor, Patriotic Decorations / Price: 10.98 | D5: B0GZGMLGDD | E5: 250TH_DOORSIGN_DAIBANG | F5: 1 | H5: 10.98 | L5: -5.26 | O5: 5.72 | Q5: 5.72 | R5: 52.09
A6: 111-6002479-2648245 / Shipped / COG: 3 / FBA | B6: 46176 | C6: Musemory Magnetic Reward Jar, 9" DIY Name 40+ Tokens Star Face Magnetic Reward Jar Gifts for Classroom, Classroom Management Tool, Reward Jars for Kids Magnetic, Back to School Gift for Kids / Price: 21.98 | D6: B0FBM5TDLH | E6: REWARDJAR_STAR | F6: 1 | H6: 21.98 | L6: -7.72 | M6: -3 | O6: 11.26 | Q6: 11.26 | R6: 51.23 | S6: 375.33
A7: 111-1013291-1045011 / Shipped / COG: 1.2 / FBA | B7: 46176 | C7: Musemory 60 Positive Cards Turtle Jar, Affirmation Cards For Women, Friendship Gift, Best Friend Gift, Positive Decor, Sea Turtle Gifts, Card Turtle for Her, Decoration For Home Office / Price: 13.99 | D7: B0F9PGKBX2 | E7: POSITIVEJAR_TURTLE | F7: 1 | H7: 13.99 | L7: -6.17 | M7: -1.2 | O7: 6.62 | Q7: 6.62 | R7: 47.32 | S7: 551.67
A8: 113-3599387-5974614 / Shipped / COG: 2.5 / FBA | B8: 46176 | C8: Reasons Why I Love You Mom Jar, DIY Love Notes in a Jar with Envelopes, What I Love About Mom, Mothers Day Gifts for Mom from Daughter Son, Mother Birthday Gifts / Price: 13.98 | D8: B0GSDQ2CQ6 | E8: MOTHERDAY_ILOVEYOUMOM | F8: 1 | H8: 13.98 | L8: -6.17 | M8: -2.5 | O8: 5.31 | Q8: 5.31 | R8: 37.98 | S8: 212.40
A9: 112-1905962-6865832 / Shipped / COG: 0 / FBA | B9: 46176 | C9: First Day Last Day of School Board Sign for Kids, First Day of Daycare Sign, Back To School Board Sign, Forst Day of School Sign, First Day of School Board - Back to School Kids Supplies Preschool / Price: 15.98 | D9: B0FDWNP259 | E9: SCHOOLBOARD_02 | F9: 1 | H9: 15.98 | L9: -6.21 | O9: 9.77 | Q9: 9.77 | R9: 61.14
A10: 113-2732469-4371414 / Shipped / COG: 0 / FBA | B10: 46176 | C10: 250th Anniversary Decorations for Home, Patriotic Door Sign, America 250th Birthday Decor, Fourth of July Decorations, USA 1776-2026 Hanging Wall Plaque, Patriotic Decorations for Front Door / Price: 12.99 | D10: B0GZHBKGCM | E10: 250TH_DOORSIGN_250THANNIVERSARY | F10: 1 | H10: 12.99 | L10: -2.15 | O10: 10.84 | Q10: 10.84 | R10: 83.45
A11: 114-4630566-4120248 / Shipped / COG: 0 / FBA | B11: 46176 | C11: 250th Anniversary Decorations for Home, Patriotic Eagle Door Sign, America 250th Birthday Decor, Fourth of July Decorations, USA Independence Day Hanging Wall Decor, Patriotic Decorations / Price: 10.98 | D11: B0GZGMLGDD | E11: 250TH_DOORSIGN_DAIBANG | F11: 1 | H11: 10.98 | L11: -5.26 | O11: 5.72 | Q11: 5.72 | R11: 52.09
A12: 111-5871499-1533841 / Shipped / COG: 0 / FBA | B12: 46176 | C12: 250th Anniversary Decorations for Home, Patriotic Eagle Door Sign, America 250th Birthday Decor, Fourth of July Decorations, USA Independence Day Hanging Wall Decor, Patriotic Decorations / Price: 10.98 | D12: B0GZGMLGDD | E12: 250TH_DOORSIGN_DAIBANG | F12: 1 | H12: 10.98 | L12: -5.26 | O12: 5.72 | Q12: 5.72 | R12: 52.09
A13: 112-6274610-6221005 / Shipped / COG: 0 / FBA | B13: 46176 | C13: Funny Card for Dad from Daughter, Son, Kids on Fathers Day - Heartfelt Message to Father, Perfect for Birthday, Father's Day, Humorous Dad Greeting Cards, Gifts for Dad (Eyes Closed TV Watching) / Price: 5.99 | D13: B0F8VM1HS2 | E13: Y3-9FHG-0UWD | F13: 1 | H13: 5.99 | L13: -3.51 | O13: 2.48 | Q13: 2.48 | R13: 41.40
A14: 113-3236592-9629018 / Shipped / COG: 3 / FBA | B14: 46176 | C14: Musemory Magnetic Reward Jar, Personalized Smiley Tokens Reward Jar for Kids, DIY, Reward Jar, Classroom Management Tool, Reward Jars for Kids Magnetic, Back to School Gift for Kids / Price: 15.98 | D14: B0F5V9Z11R | E14: UY-AO7W-2FWB | F14: 1 | H14: 15.98 | L14: -6.25 | M14: -3 | O14: 6.73 | Q14: 6.73 | R14: 42.12 | S14: 224.33
A15: 112-1859494-0931441 / Shipped / COG: 1.5 / FBA | B15: 46176 | C15: Musemory 60 Positive Sunshine Cards Jar, Sunshine Gifts, Affirmation Cards Sunshine For Women, Friendship Gift, Positive Decor, Key Chain Sunshine / Price: 12.99 | D15: B0F9PFJ2C9 | E15: POSITIVEJAR_CLOUDSUN | F15: 1 | H15: 12.99 | L15: -6.24 | M15: -1.5 | O15: 5.25 | Q15: 5.25 | R15: 40.42 | S15: 350.00
A16: 112-5873300-7991404 / Shipped / COG: 3 / FBA | B16: 46176 | C16: Musemory Magnetic Reward Jar, Personalized Smiley Tokens Reward Jar for Kids, DIY, Reward Jar, Classroom Management Tool, Reward Jars for Kids Magnetic, Back to School Gift for Kids / Price: 15.98 | D16: B0F5V9Z11R | E16: UY-AO7W-2FWB | F16: 1 | H16: 15.98 | L16: -6.25 | M16: -3 | O16: 6.73 | Q16: 6.73 | R16: 42.12 | S16: 224.33
A17: 112-0413892-2476221 / Shipped / COG: 0 / FBA | B17: 46176 | C17: 250th Anniversary Decorations for Home, Patriotic Eagle Door Sign, America 250th Birthday Decor, Fourth of July Decorations, USA Independence Day Hanging Wall Decor, Patriotic Decorations / Price: 10.98 | D17: B0GZGMLGDD | E17: 250TH_DOORSIGN_DAIBANG | F17: 1 | H17: 10.98 | L17: -5.26 | O17: 5.72 | Q17: 5.72 | R17: 52.09
A18: 112-7789653-2173044 / Shipped / COG: 0 / FBA | B18: 46176 | C18: Dad Joke Jar, Gifts Set with Card Hat, Gag Gift for Men, Joke Cards Jar, Fathers Day Gift, Birthday Present for Husband, Fun Family Game Night Humor Kit / Price: 7.98 | D18: B0GWQF4FM6 | E18: FATHERDAY_DADJOKESJAR | F18: 1 | H18: 7.98 | L18: -4.33 | O18: 3.65 | Q18: 3.65 | R18: 45.74
A19: 114-8378838-6327435 / Shipped / COG: 0 / FBA | B19: 46176 | C19: Dad Hat, Best Dad Ever Flag Hat, Fathers Day Birthday Gift for Papa from Daughter Son, Trucker Hat for Men, Gift for Dad / Price: 15.98 | D19: B0GWRC6XR9 | E19: FATHERDAY_DADHAT | F19: 1 | H19: 15.98 | L19: -2.64 | O19: 13.34 | Q19: 13.34 | R19: 83.48
A20: 114-6525818-1042646 / Shipped / COG: 0 / FBA | B20: 46176 | C20: Funny Nurse Badge Reel Retractable ID Holder – Cute Duck Nurse Badge Clip for RN CNA LPN, Medical ID Badge Holder for Scrubs, Gift Idea (Cuff) / Price: 7.98 | D20: B0GVZ1733Q | E20: NURSEBADGEREEL_CUFFEM | F20: 1 | H20: 7.98 | L20: -1.32 | O20: 6.66 | Q20: 6.66 | R20: 83.46
A21: 114-0050202-1860221 / Shipped / COG: 0 / FBA | B21: 46176 | C21: Best Dad Ever American Flag Hat / Price: 17.98 | D21: B0GY4JSS94 | E21: FATHERDAY_BESTDADEVERHAT | F21: 1 | H21: 17.98 | L21: -5.19 | O21: 12.79 | Q21: 12.79 | R21: 71.13
A22: 114-9338939-3335460 / Shipped / COG: 2.5 / FBA | B22: 46176 | C22: Musemory I Love You Because Jar, Father Day Gifts, 60 Blank Heart Notes, Love Notes, Birthday Gifts for Mom Women Wife Grandma from Son, Romantic Personalized Gift for Wife, Husband / Price: 13.99 | D22: B0GFKLJQFJ | E22: VLT_ILOVEYOUBECAUSE | F22: 1 | H22: 13.99 | L22: -6.17 | M22: -2.5 | O22: 5.32 | Q22: 5.32 | R22: 38.03 | S22: 212.80
A23: 113-5174170-4848260 / Shipped / COG: 0 / FBA | B23: 46176 | C23: Positive Baseball Affirmation Jar – 60 Motivational Messages for Players, Sports Lovers, Cute Baseball Gift for Kids, Teens, Athletes | Encouragement Jar, Gifts for Teen Boy / Price: 11.99 | D23: B0FXGWJZL4 | E23: POSITIVEJAR_BASEBALL | F23: 1 | H23: 11.99 | L23: -5.84 | O23: 6.15 | Q23: 6.15 | R23: 51.29
A24: 112-0714318-1746612 / Shipped / COG: 0 / FBA | B24: 46176 | C24: 250th Anniversary USA Ornament 1776 –2026, America 250 Eagle Patriotic Tabletop Decoration, 4th of JulyDecorations, Patriotic Gift for Veterans Independence Day / Price: 14.98 | D24: B0GVYTQLYB | E24: DESK-DECOR_AMERICA250 | F24: 1 | H24: 14.98 | L24: -5.98 | O24: 9.00 | Q24: 9.00 | R24: 60.08
A25: 111-5883462-6720216 / Shipped / COG: 0 / FBA | B25: 46176 | C25: Nursing 2026 Graduation Gift, Nurse Gifts for Women, Nursing Ornament, Appreciation Gifts for Women, New Nurse Gift, Gifts for Nurses / Price: 9.98 | D25: B0F62HNF16 | E25: ONM_NURSE | F25: 1 | H25: 9.98 | L25: -4.66 | O25: 5.32 | Q25: 5.32 | R25: 53.31
A26: 112-3344212-9529028 / Shipped / COG: 1.5 / FBA | B26: 46176 | C26: Musemory 60 Positive Sunshine Cards Jar, Sunshine Gifts, Affirmation Cards Sunshine For Women, Friendship Gift, Positive Decor, Key Chain Sunshine / Price: 12.99 | D26: B0F9PFJ2C9 | E26: POSITIVEJAR_CLOUDSUN | F26: 1 | H26: 12.99 | L26: -6.24 | M26: -1.5 | O26: 5.25 | Q26: 5.25 | R26: 40.42 | S26: 350.00
A27: 111-8486162-9769063 / Shipped / COG: 0 / FBA | B27: 46176 | C27: Dad Hat, Best Dad Ever Flag Hat, Fathers Day Birthday Gift for Papa from Daughter Son, Trucker Hat for Men, Gift for Dad / Price: 15.98 | D27: B0GWRC6XR9 | E27: FATHERDAY_DADHAT | F27: 1 | H27: 15.98 | L27: -7.4 | O27: 8.58 | Q27: 8.58 | R27: 53.69
A28: 114-2274947-3430663 / Shipped / COG: 0 / FBA | B28: 46176 | C28: 250th Anniversary USA Ornament 1776 –2026, America 250 Eagle Patriotic Tabletop Decoration, 4th of JulyDecorations, Patriotic Gift for Veterans Independence Day / Price: 14.98 | D28: B0GVYTQLYB | E28: DESK-DECOR_AMERICA250 | F28: 2 | H28: 29.96 | L28: -11.95 | O28: 46040 | Q28: 46040 | R28: 60.11
A29: 111-9970460-8529829 / Shipped / COG: 0 / FBA | B29: 46176 | C29: Funny Nurse Badge Reel Retractable ID Holder – Cute Duck Nurse Badge Clip for RN CNA LPN, Medical ID Badge Holder for Scrubs, Gift Idea (Stick) / Price: 7.98 | D29: B0GVYXMMNX | E29: NURSEBADGEREEL_STICKEM | F29: 1 | H29: 7.98 | L29: -1.32 | O29: 6.66 | Q29: 6.66 | R29: 83.46
A30: 113-9785006-5172245 / Shipped / COG: 0 / FBA | B30: 46176 | C30: Romantic Wedding Gift for Couple, Wooden Heart Tree Tabletop Decor with “Our Adventure Begins”, Wedding Gift for Husband Wife, Engagement Bridal Shower Newlywed Home Decor / Price: 9.99 | D30: B0H1LJX4T9 | E30: WEDDING_DEVOM_OURADVENTUREBEGIN | F30: 1 | H30: 9.99 | L30: -4.89 | O30: 46300 | Q30: 46300 | R30: 51.05
A31: 113-4845767-1605832 / Shipped / COG: 3 / FBA | B31: 46176 | C31: Musemory Magnetic Reward Jar, Personalized Smiley Tokens Reward Jar for Kids, DIY, Reward Jar, Classroom Management Tool, Reward Jars for Kids Magnetic, Back to School Gift for Kids / Price: 15.98 | D31: B0F5V9Z11R | E31: UY-AO7W-2FWB | F31: 1 | H31: 15.98 | L31: -6.25 | M31: -3 | O31: 6.73 | Q31: 6.73 | R31: 42.12 | S31: 224.33
A32: 112-5467204-8750611 / Shipped / COG: 0 / FBA | B32: 46176 | C32: 2 PCS Resist Vinyl Sticker Decal, Statue of Liberty New York Vinyl Sticker Decal – 5'' Laptop, Car, Bumper, Travel Luggage Sticker, Resist Sticker / Price: 5.89 | D32: B0F2T9B1Y2 | E32: CS-S8XU-RCDA | F32: 1 | H32: 5.89 | L32: -3.49 | O32: 2.40 | Q32: 2.40 | R32: 40.75
A33: 114-3386045-0685041 / Shipped / COG: 0 / FBA | B33: 46176 | C33: Magnetic Acrylic Car Visor Photo Clip, Father's Day, Birthday Gift For Dad, Picture Holder with Love Message, Drive Safe Car Accessory For Dad, Best Dad Ever Gifts, Birthday Gifts from Daughter / Price: 9.98 | D33: B0F8VBSG3T | E33: CARVISOR_DAD | F33: 1 | H33: 9.98 | L33: -4.52 | O33: 5.46 | Q33: 5.46 | R33: 54.71
A34: 111-4976673-9831434 / Shipped / COG: 0 / FBA | B34: 46176 | C34: Scratch Off Map of United States, All 63 US National Parks Scratch Off Poster, Scratch Off World Map, Travel Scratch Off Map, Us Map for Travel Tracking, Valentine Gift, Valentine Gifts For Her, Valentine Gift For Men / Price: 17.89 | D34: B0DJR4343W | E34: PU-2DN9-R32Y | F34: 1 | H34: 17.89 | L34: -7.3 | O34: 10.59 | Q34: 10.59 | R34: 59.20
A35: 111-1292153-4599429 / Shipped / COG: 1 / FBA | B35: 46176 | C35: 50 Positive Messages in Bottle,Anxiety Relief Items, Stress Relief, Self Care Kit for Mediation,Positive Affirmation Gifts for Women, Self Care Kit for Mediation, Unique Health and Wellness Gifts / Price: 15.98 | D35: B0CSJZLTP5 | E35: LY-IU2S-D65B | F35: 1 | H35: 15.98 | L35: -6.5 | M35: -1 | O35: 8.48 | Q35: 8.48 | R35: 53.07 | S35: 848.00
A36: 114-6107595-3545812 / Shipped / COG: 0 / FBA | B36: 46176 | C36: Magnetic Acrylic Car Visor Photo Clip, Father's Day, Birthday Gift For Dad, Picture Holder with Love Message, Drive Safe Car Accessory For Dad, Best Dad Ever Gifts, Birthday Gifts from Daughter / Price: 9.98 | D36: B0F8VBSG3T | E36: CARVISOR_DAD | F36: 1 | H36: 9.98 | L36: -4.52 | O36: 5.46 | Q36: 5.46 | R36: 54.71
A37: 112-6793310-9839468 / Shipped / COG: 1.2 / FBA | B37: 46176 | C37: Musemory 60 Positive Cards Turtle Jar, Affirmation Cards For Women, Friendship Gift, Best Friend Gift, Positive Decor, Sea Turtle Gifts, Card Turtle for Her, Decoration For Home Office / Price: 13.99 | D37: B0F9PGKBX2 | E37: POSITIVEJAR_TURTLE | F37: 1 | H37: 13.99 | L37: -6.17 | M37: -1.2 | O37: 6.62 | Q37: 6.62 | R37: 47.32 | S37: 551.67
A38: 113-1546338-7769832 / Shipped / COG: 1 / FBA | B38: 46176 | C38: Positive Affirmations Jar, Positive Affirmation Cards for Women, Unique for Women, Birthday Gifts for Women, Affirmation Cards for Men, Valentines day Gifts / Price: 7.98 | D38: B0F1Y83S8W | E38: WT-NW9C-FZDB | F38: 1 | H38: 7.98 | L38: -4.56 | M38: -1 | O38: 2.42 | Q38: 2.42 | R38: 30.33 | S38: 242.00
A39: 114-4620966-0408249 / Shipped / COG: 0 / FBA | B39: 46176 | C39: Our Daily Bread Bible Verse Jar, Bible Jar, Christian Gifts for Women, Inspirational Scriptures for Women, Daughters, Bible Accessories, Christian Gift for Young Men or Teen / Price: 11.99 | D39: B0F8N9HQHN | E39: bible jar_bread | F39: 1 | H39: 11.99 | L39: -6.07 | O39: 5.92 | Q39: 5.92 | R39: 49.37
A40: 111-3498099-5675433 / Shipped / COG: 0 / FBA | B40: 46176 | C40: Magnetic Acrylic Car Visor Photo Clip, Father's Day, Birthday Gift For Dad, Picture Holder with Love Message, Drive Safe Car Accessory For Dad, Best Dad Ever Gifts, Birthday Gifts from Daughter / Price: 9.98 | D40: B0F8VBSG3T | E40: CARVISOR_DAD | F40: 1 | H40: 9.98 | L40: -4.52 | O40: 5.46 | Q40: 5.46 | R40: 54.71
...

Sheet Clone (2)
A1: Order number | B1: Order date | C1: Product | D1: ASIN | E1: SKU | F1: Units | G1: Refunds | H1: Sales | I1: Promo | J1: Sellable Quota | K1: Refund сost | L1: Amazon fees | M1: Cost of Goods | N1: Shipping | O1: Gross profit | P1: Expenses | Q1: Net profit | R1: Margin | S1: ROI | T1: Coupon | U1: Comment
A2: 111-1013291-1045011 | B2: 46176 | C2: Musemory 60 Positive Cards Turtle Jar, Affirmation Cards For Women, Friendship Gift, Best Friend Gift, Positive Decor, Sea Turtle Gifts, Card Turtle for Her, Decoration For Home Office | D2: B0F9PGKBX2 | E2: POSITIVEJAR_TURTLE | F2: 1 | H2: 13.99 | L2: -6.17 | M2: -1.2 | O2: 6.62 | Q2: 6.62 | R2: 47.32 | S2: 551.67
A3: 111-1292153-4599429 | B3: 46176 | C3: 50 Positive Messages in Bottle,Anxiety Relief Items, Stress Relief, Self Care Kit for Mediation,Positive Affirmation Gifts for Women, Self Care Kit for Mediation, Unique Health and Wellness Gifts | D3: B0CSJZLTP5 | E3: LY-IU2S-D65B | F3: 1 | H3: 15.98 | L3: -6.5 | M3: -1 | O3: 8.48 | Q3: 8.48 | R3: 53.07 | S3: 848.00
A4: 111-2123246-7694605 | B4: 46176 | C4: Dad Hat, Best Dad Ever Flag Hat, Fathers Day Birthday Gift for Papa from Daughter Son, Trucker Hat for Men, Gift for Dad | D4: B0GWRC6XR9 | E4: FATHERDAY_DADHAT | F4: 1 | H4: 15.98 | L4: -6.43 | O4: 9.55 | Q4: 9.55 | R4: 59.76
A5: 111-2348073-4114606 | B5: 46176 | C5: Friendship Elephant Ornament with Story Card, Gifts for Women, Friendship Birthday Gifts for Women, Birthday Presents for Best Friends Sisters Special Bond Decor (Sunflower Elephant) | D5: B0FDQCBNZW | E5: ONM_ELEPHANT_02 | F5: 1 | H5: 6.99 | L5: -3.68 | O5: 3.31 | Q5: 3.31 | R5: 47.35
A6: 111-3498099-5675433 | B6: 46176 | C6: Magnetic Acrylic Car Visor Photo Clip, Father's Day, Birthday Gift For Dad, Picture Holder with Love Message, Drive Safe Car Accessory For Dad, Best Dad Ever Gifts, Birthday Gifts from Daughter | D6: B0F8VBSG3T | E6: CARVISOR_DAD | F6: 1 | H6: 9.98 | L6: -4.52 | O6: 5.46 | Q6: 5.46 | R6: 54.71
A7: 111-4976673-9831434 | B7: 46176 | C7: Scratch Off Map of United States, All 63 US National Parks Scratch Off Poster, Scratch Off World Map, Travel Scratch Off Map, Us Map for Travel Tracking, Valentine Gift, Valentine Gifts For Her, Valentine Gift For Men | D7: B0DJR4343W | E7: PU-2DN9-R32Y | F7: 1 | H7: 17.89 | L7: -7.3 | O7: 10.59 | Q7: 10.59 | R7: 59.20
A8: 111-5871499-1533841 | B8: 46176 | C8: 250th Anniversary Decorations for Home, Patriotic Eagle Door Sign, America 250th Birthday Decor, Fourth of July Decorations, USA Independence Day Hanging Wall Decor, Patriotic Decorations | D8: B0GZGMLGDD | E8: 250TH_DOORSIGN_DAIBANG | F8: 1 | H8: 10.98 | L8: -5.26 | O8: 5.72 | Q8: 5.72 | R8: 52.09
A9: 111-5883462-6720216 | B9: 46176 | C9: Nursing 2026 Graduation Gift, Nurse Gifts for Women, Nursing Ornament, Appreciation Gifts for Women, New Nurse Gift, Gifts for Nurses | D9: B0F62HNF16 | E9: ONM_NURSE | F9: 1 | H9: 9.98 | L9: -4.66 | O9: 5.32 | Q9: 5.32 | R9: 53.31
A10: 111-6002479-2648245 | B10: 46176 | C10: Musemory Magnetic Reward Jar, 9" DIY Name 40+ Tokens Star Face Magnetic Reward Jar Gifts for Classroom, Classroom Management Tool, Reward Jars for Kids Magnetic, Back to School Gift for Kids | D10: B0FBM5TDLH | E10: REWARDJAR_STAR | F10: 1 | H10: 21.98 | L10: -7.72 | M10: -3 | O10: 11.26 | Q10: 11.26 | R10: 51.23 | S10: 375.33
A11: 111-8486162-9769063 | B11: 46176 | C11: Dad Hat, Best Dad Ever Flag Hat, Fathers Day Birthday Gift for Papa from Daughter Son, Trucker Hat for Men, Gift for Dad | D11: B0GWRC6XR9 | E11: FATHERDAY_DADHAT | F11: 1 | H11: 15.98 | L11: -7.4 | O11: 8.58 | Q11: 8.58 | R11: 53.69
A12: 111-9439137-1446627 | B12: 46176 | C12: Read Me When Bible Verse Jar, Bible Accessories, Prayer Jar, Graduation for Her, Christian Gift For Women, Teacher Gifts, Fathers Day Gift For Dad (Bible Jar for Daughter) | D12: B0F7RL4G2Q | E12: bible jar_daughter | F12: 1 | H12: 11.99 | L12: -6.07 | O12: 5.92 | Q12: 5.92 | R12: 49.37
A13: 111-9970460-8529829 | B13: 46176 | C13: Funny Nurse Badge Reel Retractable ID Holder – Cute Duck Nurse Badge Clip for RN CNA LPN, Medical ID Badge Holder for Scrubs, Gift Idea (Stick) | D13: B0GVYXMMNX | E13: NURSEBADGEREEL_STICKEM | F13: 1 | H13: 7.98 | L13: -1.32 | O13: 6.66 | Q13: 6.66 | R13: 83.46
A14: 112-0413892-2476221 | B14: 46176 | C14: 250th Anniversary Decorations for Home, Patriotic Eagle Door Sign, America 250th Birthday Decor, Fourth of July Decorations, USA Independence Day Hanging Wall Decor, Patriotic Decorations | D14: B0GZGMLGDD | E14: 250TH_DOORSIGN_DAIBANG | F14: 1 | H14: 10.98 | L14: -5.26 | O14: 5.72 | Q14: 5.72 | R14: 52.09
A15: 112-0714318-1746612 | B15: 46176 | C15: 250th Anniversary USA Ornament 1776 –2026, America 250 Eagle Patriotic Tabletop Decoration, 4th of JulyDecorations, Patriotic Gift for Veterans Independence Day | D15: B0GVYTQLYB | E15: DESK-DECOR_AMERICA250 | F15: 1 | H15: 14.98 | L15: -5.98 | O15: 9.00 | Q15: 9.00 | R15: 60.08
A16: 112-1859494-0931441 | B16: 46176 | C16: Musemory 60 Positive Sunshine Cards Jar, Sunshine Gifts, Affirmation Cards Sunshine For Women, Friendship Gift, Positive Decor, Key Chain Sunshine | D16: B0F9PFJ2C9 | E16: POSITIVEJAR_CLOUDSUN | F16: 1 | H16: 12.99 | L16: -6.24 | M16: -1.5 | O16: 5.25 | Q16: 5.25 | R16: 40.42 | S16: 350.00
A17: 112-1905962-6865832 | B17: 46176 | C17: First Day Last Day of School Board Sign for Kids, First Day of Daycare Sign, Back To School Board Sign, Forst Day of School Sign, First Day of School Board - Back to School Kids Supplies Preschool | D17: B0FDWNP259 | E17: SCHOOLBOARD_02 | F17: 1 | H17: 15.98 | L17: -6.21 | O17: 9.77 | Q17: 9.77 | R17: 61.14
A18: 112-3344212-9529028 | B18: 46176 | C18: Musemory 60 Positive Sunshine Cards Jar, Sunshine Gifts, Affirmation Cards Sunshine For Women, Friendship Gift, Positive Decor, Key Chain Sunshine | D18: B0F9PFJ2C9 | E18: POSITIVEJAR_CLOUDSUN | F18: 1 | H18: 12.99 | L18: -6.24 | M18: -1.5 | O18: 5.25 | Q18: 5.25 | R18: 40.42 | S18: 350.00
A19: 112-3699085-5697846 | B19: 46176 | C19: Bible Verse Jar, Christian Gifts for Women, Inspirational Scriptures for Women, Daughters, Bible Accessories, Mothers Day gifts for Mom, Decorative Glass Inspirational Scripture Jar | D19: B0D3PR4S5B | E19: bile jar-02 | F19: 1 | H19: 15.99 | L19: -6.99 | O19: 9.00 | Q19: 9.00 | R19: 56.29
A20: 112-5467204-8750611 | B20: 46176 | C20: 2 PCS Resist Vinyl Sticker Decal, Statue of Liberty New York Vinyl Sticker Decal – 5'' Laptop, Car, Bumper, Travel Luggage Sticker, Resist Sticker | D20: B0F2T9B1Y2 | E20: CS-S8XU-RCDA | F20: 1 | H20: 5.89 | L20: -3.49 | O20: 2.40 | Q20: 2.40 | R20: 40.75
A21: 112-5873300-7991404 | B21: 46176 | C21: Musemory Magnetic Reward Jar, Personalized Smiley Tokens Reward Jar for Kids, DIY, Reward Jar, Classroom Management Tool, Reward Jars for Kids Magnetic, Back to School Gift for Kids | D21: B0F5V9Z11R | E21: UY-AO7W-2FWB | F21: 1 | H21: 15.98 | L21: -6.25 | M21: -3 | O21: 6.73 | Q21: 6.73 | R21: 42.12 | S21: 224.33
A22: 112-6274610-6221005 | B22: 46176 | C22: Funny Card for Dad from Daughter, Son, Kids on Fathers Day - Heartfelt Message to Father, Perfect for Birthday, Father's Day, Humorous Dad Greeting Cards, Gifts for Dad (Eyes Closed TV Watching) | D22: B0F8VM1HS2 | E22: Y3-9FHG-0UWD | F22: 1 | H22: 5.99 | L22: -3.51 | O22: 2.48 | Q22: 2.48 | R22: 41.40
A23: 112-6793310-9839468 | B23: 46176 | C23: Musemory 60 Positive Cards Turtle Jar, Affirmation Cards For Women, Friendship Gift, Best Friend Gift, Positive Decor, Sea Turtle Gifts, Card Turtle for Her, Decoration For Home Office | D23: B0F9PGKBX2 | E23: POSITIVEJAR_TURTLE | F23: 1 | H23: 13.99 | L23: -6.17 | M23: -1.2 | O23: 6.62 | Q23: 6.62 | R23: 47.32 | S23: 551.67
A24: 112-7077440-9483408 | B24: 46176 | C24: 250th Anniversary Decorations for Home, Patriotic Eagle Door Sign, America 250th Birthday Decor, Fourth of July Decorations, USA Independence Day Hanging Wall Decor, Patriotic Decorations | D24: B0GZGMLGDD | E24: 250TH_DOORSIGN_DAIBANG | F24: 1 | H24: 10.98 | L24: -5.26 | O24: 5.72 | Q24: 5.72 | R24: 52.09
A25: 112-7789653-2173044 | B25: 46176 | C25: Dad Joke Jar, Gifts Set with Card Hat, Gag Gift for Men, Joke Cards Jar, Fathers Day Gift, Birthday Present for Husband, Fun Family Game Night Humor Kit | D25: B0GWQF4FM6 | E25: FATHERDAY_DADJOKESJAR | F25: 1 | H25: 7.98 | L25: -4.33 | O25: 3.65 | Q25: 3.65 | R25: 45.74
A26: 112-8699877-2660231 | B26: 46176 | C26: 250th Anniversary USA Ornament 1776 –2026, America 250 Eagle Patriotic Tabletop Decoration, 4th of JulyDecorations, Patriotic Gift for Veterans Independence Day | D26: B0GVYTQLYB | E26: DESK-DECOR_AMERICA250 | F26: 1 | H26: 14.98 | L26: -3.57 | O26: 11.41 | Q26: 11.41 | R26: 76.17
A27: 113-1546338-7769832 | B27: 46176 | C27: Positive Affirmations Jar, Positive Affirmation Cards for Women, Unique for Women, Birthday Gifts for Women, Affirmation Cards for Men, Valentines day Gifts | D27: B0F1Y83S8W | E27: WT-NW9C-FZDB | F27: 1 | H27: 7.98 | L27: -4.56 | M27: -1 | O27: 2.42 | Q27: 2.42 | R27: 30.33 | S27: 242.00
A28: 113-2732469-4371414 | B28: 46176 | C28: 250th Anniversary Decorations for Home, Patriotic Door Sign, America 250th Birthday Decor, Fourth of July Decorations, USA 1776-2026 Hanging Wall Plaque, Patriotic Decorations for Front Door | D28: B0GZHBKGCM | E28: 250TH_DOORSIGN_250THANNIVERSARY | F28: 1 | H28: 12.99 | L28: -2.15 | O28: 10.84 | Q28: 10.84 | R28: 83.45
A29: 113-3236592-9629018 | B29: 46176 | C29: Musemory Magnetic Reward Jar, Personalized Smiley Tokens Reward Jar for Kids, DIY, Reward Jar, Classroom Management Tool, Reward Jars for Kids Magnetic, Back to School Gift for Kids | D29: B0F5V9Z11R | E29: UY-AO7W-2FWB | F29: 1 | H29: 15.98 | L29: -6.25 | M29: -3 | O29: 6.73 | Q29: 6.73 | R29: 42.12 | S29: 224.33
A30: 113-3599387-5974614 | B30: 46176 | C30: Reasons Why I Love You Mom Jar, DIY Love Notes in a Jar with Envelopes, What I Love About Mom, Mothers Day Gifts for Mom from Daughter Son, Mother Birthday Gifts | D30: B0GSDQ2CQ6 | E30: MOTHERDAY_ILOVEYOUMOM | F30: 1 | H30: 13.98 | L30: -6.17 | M30: -2.5 | O30: 5.31 | Q30: 5.31 | R30: 37.98 | S30: 212.40
A31: 113-4845767-1605832 | B31: 46176 | C31: Musemory Magnetic Reward Jar, Personalized Smiley Tokens Reward Jar for Kids, DIY, Reward Jar, Classroom Management Tool, Reward Jars for Kids Magnetic, Back to School Gift for Kids | D31: B0F5V9Z11R | E31: UY-AO7W-2FWB | F31: 1 | H31: 15.98 | L31: -6.25 | M31: -3 | O31: 6.73 | Q31: 6.73 | R31: 42.12 | S31: 224.33
A32: 113-5174170-4848260 | B32: 46176 | C32: Positive Baseball Affirmation Jar – 60 Motivational Messages for Players, Sports Lovers, Cute Baseball Gift for Kids, Teens, Athletes | Encouragement Jar, Gifts for Teen Boy | D32: B0FXGWJZL4 | E32: POSITIVEJAR_BASEBALL | F32: 1 | H32: 11.99 | L32: -5.84 | O32: 6.15 | Q32: 6.15 | R32: 51.29
A33: 113-6802263-2738611 | B33: 46176 | C33: Badass Affirmation Jar, Inspirational Gift, Daily Affirmations for Women, Funny Affirmation Cards, Birthday Gifts for Her, Women, Valentines Day Gifts | D33: B0DM93RNKC | E33: bible jar_03 | F33: 1 | H33: 11.99 | L33: -6.33 | M33: -1.5 | O33: 4.16 | Q33: 4.16 | R33: 34.70 | S33: 277.33
A34: 113-7145139-3375448 | B34: 46176 | C34: Bible Verse Jar, Christian Gifts for Women, Inspirational Scriptures for Women, Daughters, Bible Accessories, Mothers Day gifts for Mom, Decorative Glass Inspirational Scripture Jar | D34: B0D3PR4S5B | E34: bile jar-02 | F34: 1 | H34: 15.99 | L34: -6.99 | O34: 9.00 | Q34: 9.00 | R34: 56.29
A35: 113-9785006-5172245 | B35: 46176 | C35: Romantic Wedding Gift for Couple, Wooden Heart Tree Tabletop Decor with “Our Adventure Begins”, Wedding Gift for Husband Wife, Engagement Bridal Shower Newlywed Home Décor | D35: B0H1LJX4T9 | E35: WEDDING_DEVOM_OURADVENTUREBEGIN | F35: 1 | H35: 9.99 | L35: -4.89 | O35: 46300 | Q35: 46300 | R35: 51.05
A36: 114-0050202-1860221 | B36: 46176 | C36: Best Dad Ever American Flag Hat | D36: B0GY4JSS94 | E36: FATHERDAY_BESTDADEVERHAT | F36: 1 | H36: 17.98 | L36: -5.19 | O36: 12.79 | Q36: 12.79 | R36: 71.13
A37: 114-0485677-9289868 | B37: 46176 | C37: America 250 Patriotic Gnome Decor, USA 250th Anniversary Decoration 1776-2026, Independence Day Wooden Tabletop Sign, Liberty Bell & We The People Gnome Display, Patriotic Home Office Shelf Décor | D37: B0H2LZQHTH | E37: 250TH_GNOME_AMERICA250 | F37: 1 | H37: 9.99 | L37: -4.17 | O37: 5.82 | Q37: 5.82 | R37: 58.26
A38: 114-0703451-4349053 | B38: 46176 | C38: Musemory 60 Positive Cards Turtle Jar, Affirmation Cards For Women, Friendship Gift, Best Friend Gift, Positive Decor, Sea Turtle Gifts, Card Turtle for Her, Decoration For Home Office | D38: B0F9PGKBX2 | E38: POSITIVEJAR_TURTLE | F38: 1 | H38: 13.99 | L38: -6.17 | M38: -1.2 | O38: 6.62 | Q38: 6.62 | R38: 47.32 | S38: 551.67
A39: 114-2274947-3430663 | B39: 46176 | C39: 250th Anniversary USA Ornament 1776 –2026, America 250 Eagle Patriotic Tabletop Decoration, 4th of JulyDecorations, Patriotic Gift for Veterans Independence Day | D39: B0GVYTQLYB | E39: DESK-DECOR_AMERICA250 | F39: 2 | H39: 29.96 | L39: -11.95 | O39: 46040 | Q39: 46040 | R39: 60.11
A40: 114-2565360-6033006 | B40: 46176 | C40: Funny Nurse Badge Reel Retractable ID Holder – Cute Duck Nurse Badge Clip for RN CNA LPN, Medical ID Badge Holder for Scrubs, Gift Idea (Cuff) | D40: B0GVZ1733Q | E40: NURSEBADGEREEL_CUFFEM | F40: 1 | H40: 7.98 | L40: -1.32 | O40: 6.66 | Q40: 6.66 | R40: 83.46
...

Sheet Check
A1: Order number | B1: Order date | C1: Product | D1: ASIN | E1: SKU | F1: Units | G1: Refunds | H1: Sales | I1: Promo | J1: Sellable Quota | K1: Refund сost | L1: Amazon fees | M1: Cost of Goods | N1: Shipping | O1: Gross profit | P1: Expenses | Q1: Net profit | R1: Margin | S1: ROI
A2: =EXACT(NEW_summary_order_items_rows!A2,'Clone (2)'!A2) -> TRUE | B2: =EXACT(NEW_summary_order_items_rows!B2,'Clone (2)'!B2) -> FALSE | C2: =EXACT(NEW_summary_order_items_rows!C2,'Clone (2)'!C2) -> TRUE | D2: =EXACT('Clone (2)'!D2,NEW_summary_order_items_rows!D2) -> TRUE | E2: =EXACT('Clone (2)'!E2,NEW_summary_order_items_rows!E2) -> TRUE | F2: =EXACT('Clone (2)'!F2,NEW_summary_order_items_rows!F2) -> TRUE | G2: =EXACT('Clone (2)'!G2,NEW_summary_order_items_rows!G2) -> FALSE | H2: =EXACT('Clone (2)'!H2,NEW_summary_order_items_rows!H2) -> TRUE | I2: =EXACT('Clone (2)'!I2,NEW_summary_order_items_rows!I2) -> FALSE | J2: =EXACT('Clone (2)'!J2,NEW_summary_order_items_rows!J2) -> TRUE | K2: =EXACT('Clone (2)'!K2,NEW_summary_order_items_rows!K2) -> FALSE | ... S2: =EXACT('Clone (2)'!S2,NEW_summary_order_items_rows!S2) -> FALSE
A3: =EXACT(NEW_summary_order_items_rows!A3,'Clone (2)'!A3) -> TRUE | B3: =EXACT(NEW_summary_order_items_rows!B3,'Clone (2)'!B3) -> FALSE | C3: =EXACT(NEW_summary_order_items_rows!C3,'Clone (2)'!C3) -> TRUE | D3: =EXACT('Clone (2)'!D3,NEW_summary_order_items_rows!D3) -> TRUE | E3: =EXACT('Clone (2)'!E3,NEW_summary_order_items_rows!E3) -> TRUE | F3: =EXACT('Clone (2)'!F3,NEW_summary_order_items_rows!F3) -> TRUE | G3: =EXACT('Clone (2)'!G3,NEW_summary_order_items_rows!G3) -> FALSE | H3: =EXACT('Clone (2)'!H3,NEW_summary_order_items_rows!H3) -> TRUE | I3: =EXACT('Clone (2)'!I3,NEW_summary_order_items_rows!I3) -> FALSE | J3: =EXACT('Clone (2)'!J3,NEW_summary_order_items_rows!J3) -> TRUE | K3: =EXACT('Clone (2)'!K3,NEW_summary_order_items_rows!K3) -> FALSE | ... S3: =EXACT('Clone (2)'!S3,NEW_summary_order_items_rows!S3) -> FALSE
A4: =EXACT(NEW_summary_order_items_rows!A4,'Clone (2)'!A4) -> TRUE | B4: =EXACT(NEW_summary_order_items_rows!B4,'Clone (2)'!B4) -> FALSE | C4: =EXACT(NEW_summary_order_items_rows!C4,'Clone (2)'!C4) -> TRUE | D4: =EXACT('Clone (2)'!D4,NEW_summary_order_items_rows!D4) -> TRUE | E4: =EXACT('Clone (2)'!E4,NEW_summary_order_items_rows!E4) -> TRUE | F4: =EXACT('Clone (2)'!F4,NEW_summary_order_items_rows!F4) -> TRUE | G4: =EXACT('Clone (2)'!G4,NEW_summary_order_items_rows!G4) -> FALSE | H4: =EXACT('Clone (2)'!H4,NEW_summary_order_items_rows!H4) -> TRUE | I4: =EXACT('Clone (2)'!I4,NEW_summary_order_items_rows!I4) -> FALSE | J4: =EXACT('Clone (2)'!J4,NEW_summary_order_items_rows!J4) -> TRUE | K4: =EXACT('Clone (2)'!K4,NEW_summary_order_items_rows!K4) -> FALSE | ... S4: =EXACT('Clone (2)'!S4,NEW_summary_order_items_rows!S4) -> TRUE
A5: =EXACT(NEW_summary_order_items_rows!A5,'Clone (2)'!A5) -> TRUE | B5: =EXACT(NEW_summary_order_items_rows!B5,'Clone (2)'!B5) -> FALSE | C5: =EXACT(NEW_summary_order_items_rows!C5,'Clone (2)'!C5) -> TRUE | D5: =EXACT('Clone (2)'!D5,NEW_summary_order_items_rows!D5) -> TRUE | E5: =EXACT('Clone (2)'!E5,NEW_summary_order_items_rows!E5) -> TRUE | F5: =EXACT('Clone (2)'!F5,NEW_summary_order_items_rows!F5) -> TRUE | G5: =EXACT('Clone (2)'!G5,NEW_summary_order_items_rows!G5) -> FALSE | H5: =EXACT('Clone (2)'!H5,NEW_summary_order_items_rows!H5) -> TRUE | I5: =EXACT('Clone (2)'!I5,NEW_summary_order_items_rows!I5) -> FALSE | J5: =EXACT('Clone (2)'!J5,NEW_summary_order_items_rows!J5) -> TRUE | K5: =EXACT('Clone (2)'!K5,NEW_summary_order_items_rows!K5) -> FALSE | ... S5: =EXACT('Clone (2)'!S5,NEW_summary_order_items_rows!S5) -> TRUE
A6: =EXACT(NEW_summary_order_items_rows!A6,'Clone (2)'!A6) -> TRUE | B6: =EXACT(NEW_summary_order_items_rows!B6,'Clone (2)'!B6) -> FALSE | C6: =EXACT(NEW_summary_order_items_rows!C6,'Clone (2)'!C6) -> TRUE | D6: =EXACT('Clone (2)'!D6,NEW_summary_order_items_rows!D6) -> TRUE | E6: =EXACT('Clone (2)'!E6,NEW_summary_order_items_rows!E6) -> TRUE | F6: =EXACT('Clone (2)'!F6,NEW_summary_order_items_rows!F6) -> TRUE | G6: =EXACT('Clone (2)'!G6,NEW_summary_order_items_rows!G6) -> FALSE | H6: =EXACT('Clone (2)'!H6,NEW_summary_order_items_rows!H6) -> TRUE | I6: =EXACT('Clone (2)'!I6,NEW_summary_order_items_rows!I6) -> FALSE | J6: =EXACT('Clone (2)'!J6,NEW_summary_order_items_rows!J6) -> TRUE | K6: =EXACT('Clone (2)'!K6,NEW_summary_order_items_rows!K6) -> FALSE | ... S6: =EXACT('Clone (2)'!S6,NEW_summary_order_items_rows!S6) -> TRUE
A7: =EXACT(NEW_summary_order_items_rows!A7,'Clone (2)'!A7) -> TRUE | B7: =EXACT(NEW_summary_order_items_rows!B7,'Clone (2)'!B7) -> FALSE | C7: =EXACT(NEW_summary_order_items_rows!C7,'Clone (2)'!C7) -> FALSE | D7: =EXACT('Clone (2)'!D7,NEW_summary_order_items_rows!D7) -> TRUE | E7: =EXACT('Clone (2)'!E7,NEW_summary_order_items_rows!E7) -> TRUE | F7: =EXACT('Clone (2)'!F7,NEW_summary_order_items_rows!F7) -> TRUE | G7: =EXACT('Clone (2)'!G7,NEW_summary_order_items_rows!G7) -> FALSE | H7: =EXACT('Clone (2)'!H7,NEW_summary_order_items_rows!H7) -> TRUE | I7: =EXACT('Clone (2)'!I7,NEW_summary_order_items_rows!I7) -> FALSE | J7: =EXACT('Clone (2)'!J7,NEW_summary_order_items_rows!J7) -> TRUE | K7: =EXACT('Clone (2)'!K7,NEW_summary_order_items_rows!K7) -> FALSE | ... S7: =EXACT('Clone (2)'!S7,NEW_summary_order_items_rows!S7) -> TRUE
A8: =EXACT(NEW_summary_order_items_rows!A8,'Clone (2)'!A8) -> TRUE | B8: =EXACT(NEW_summary_order_items_rows!B8,'Clone (2)'!B8) -> FALSE | C8: =EXACT(NEW_summary_order_items_rows!C8,'Clone (2)'!C8) -> TRUE | D8: =EXACT('Clone (2)'!D8,NEW_summary_order_items_rows!D8) -> TRUE | E8: =EXACT('Clone (2)'!E8,NEW_summary_order_items_rows!E8) -> TRUE | F8: =EXACT('Clone (2)'!F8,NEW_summary_order_items_rows!F8) -> TRUE | G8: =EXACT('Clone (2)'!G8,NEW_summary_order_items_rows!G8) -> FALSE | H8: =EXACT('Clone (2)'!H8,NEW_summary_order_items_rows!H8) -> TRUE | I8: =EXACT('Clone (2)'!I8,NEW_summary_order_items_rows!I8) -> FALSE | J8: =EXACT('Clone (2)'!J8,NEW_summary_order_items_rows!J8) -> TRUE | K8: =EXACT('Clone (2)'!K8,NEW_summary_order_items_rows!K8) -> FALSE | ... S8: =EXACT('Clone (2)'!S8,NEW_summary_order_items_rows!S8) -> TRUE
A9: =EXACT(NEW_summary_order_items_rows!A9,'Clone (2)'!A9) -> TRUE | B9: =EXACT(NEW_summary_order_items_rows!B9,'Clone (2)'!B9) -> FALSE | C9: =EXACT(NEW_summary_order_items_rows!C9,'Clone (2)'!C9) -> TRUE | D9: =EXACT('Clone (2)'!D9,NEW_summary_order_items_rows!D9) -> TRUE | E9: =EXACT('Clone (2)'!E9,NEW_summary_order_items_rows!E9) -> TRUE | F9: =EXACT('Clone (2)'!F9,NEW_summary_order_items_rows!F9) -> TRUE | G9: =EXACT('Clone (2)'!G9,NEW_summary_order_items_rows!G9) -> FALSE | H9: =EXACT('Clone (2)'!H9,NEW_summary_order_items_rows!H9) -> TRUE | I9: =EXACT('Clone (2)'!I9,NEW_summary_order_items_rows!I9) -> FALSE | J9: =EXACT('Clone (2)'!J9,NEW_summary_order_items_rows!J9) -> TRUE | K9: =EXACT('Clone (2)'!K9,NEW_summary_order_items_rows!K9) -> FALSE | ... S9: =EXACT('Clone (2)'!S9,NEW_summary_order_items_rows!S9) -> TRUE
A10: =EXACT(NEW_summary_order_items_rows!A10,'Clone (2)'!A10) -> TRUE | B10: =EXACT(NEW_summary_order_items_rows!B10,'Clone (2)'!B10) -> FALSE | C10: =EXACT(NEW_summary_order_items_rows!C10,'Clone (2)'!C10) -> TRUE | D10: =EXACT('Clone (2)'!D10,NEW_summary_order_items_rows!D10) -> TRUE | E10: =EXACT('Clone (2)'!E10,NEW_summary_order_items_rows!E10) -> TRUE | F10: =EXACT('Clone (2)'!F10,NEW_summary_order_items_rows!F10) -> TRUE | G10: =EXACT('Clone (2)'!G10,NEW_summary_order_items_rows!G10) -> FALSE | H10: =EXACT('Clone (2)'!H10,NEW_summary_order_items_rows!H10) -> TRUE | I10: =EXACT('Clone (2)'!I10,NEW_summary_order_items_rows!I10) -> FALSE | J10: =EXACT('Clone (2)'!J10,NEW_summary_order_items_rows!J10) -> TRUE | K10: =EXACT('Clone (2)'!K10,NEW_summary_order_items_rows!K10) -> FALSE | ... S10: =EXACT('Clone (2)'!S10,NEW_summary_order_items_rows!S10) -> FALSE
A11: =EXACT(NEW_summary_order_items_rows!A11,'Clone (2)'!A11) -> TRUE | B11: =EXACT(NEW_summary_order_items_rows!B11,'Clone (2)'!B11) -> FALSE | C11: =EXACT(NEW_summary_order_items_rows!C11,'Clone (2)'!C11) -> TRUE | D11: =EXACT('Clone (2)'!D11,NEW_summary_order_items_rows!D11) -> TRUE | E11: =EXACT('Clone (2)'!E11,NEW_summary_order_items_rows!E11) -> TRUE | F11: =EXACT('Clone (2)'!F11,NEW_summary_order_items_rows!F11) -> TRUE | G11: =EXACT('Clone (2)'!G11,NEW_summary_order_items_rows!G11) -> FALSE | H11: =EXACT('Clone (2)'!H11,NEW_summary_order_items_rows!H11) -> TRUE | I11: =EXACT('Clone (2)'!I11,NEW_summary_order_items_rows!I11) -> FALSE | J11: =EXACT('Clone (2)'!J11,NEW_summary_order_items_rows!J11) -> TRUE | K11: =EXACT('Clone (2)'!K11,NEW_summary_order_items_rows!K11) -> FALSE | ... S11: =EXACT('Clone (2)'!S11,NEW_summary_order_items_rows!S11) -> TRUE
A12: =EXACT(NEW_summary_order_items_rows!A12,'Clone (2)'!A12) -> TRUE | B12: =EXACT(NEW_summary_order_items_rows!B12,'Clone (2)'!B12) -> FALSE | C12: =EXACT(NEW_summary_order_items_rows!C12,'Clone (2)'!C12) -> TRUE | D12: =EXACT('Clone (2)'!D12,NEW_summary_order_items_rows!D12) -> TRUE | E12: =EXACT('Clone (2)'!E12,NEW_summary_order_items_rows!E12) -> TRUE | F12: =EXACT('Clone (2)'!F12,NEW_summary_order_items_rows!F12) -> TRUE | G12: =EXACT('Clone (2)'!G12,NEW_summary_order_items_rows!G12) -> FALSE | H12: =EXACT('Clone (2)'!H12,NEW_summary_order_items_rows!H12) -> TRUE | I12: =EXACT('Clone (2)'!I12,NEW_summary_order_items_rows!I12) -> FALSE | J12: =EXACT('Clone (2)'!J12,NEW_summary_order_items_rows!J12) -> TRUE | K12: =EXACT('Clone (2)'!K12,NEW_summary_order_items_rows!K12) -> FALSE | ... S12: =EXACT('Clone (2)'!S12,NEW_summary_order_items_rows!S12) -> TRUE
A13: =EXACT(NEW_summary_order_items_rows!A13,'Clone (2)'!A13) -> TRUE | B13: =EXACT(NEW_summary_order_items_rows!B13,'Clone (2)'!B13) -> FALSE | C13: =EXACT(NEW_summary_order_items_rows!C13,'Clone (2)'!C13) -> FALSE | D13: =EXACT('Clone (2)'!D13,NEW_summary_order_items_rows!D13) -> TRUE | E13: =EXACT('Clone (2)'!E13,NEW_summary_order_items_rows!E13) -> TRUE | F13: =EXACT('Clone (2)'!F13,NEW_summary_order_items_rows!F13) -> TRUE | G13: =EXACT('Clone (2)'!G13,NEW_summary_order_items_rows!G13) -> FALSE | H13: =EXACT('Clone (2)'!H13,NEW_summary_order_items_rows!H13) -> TRUE | I13: =EXACT('Clone (2)'!I13,NEW_summary_order_items_rows!I13) -> FALSE | J13: =EXACT('Clone (2)'!J13,NEW_summary_order_items_rows!J13) -> TRUE | K13: =EXACT('Clone (2)'!K13,NEW_summary_order_items_rows!K13) -> FALSE | ... S13: =EXACT('Clone (2)'!S13,NEW_summary_order_items_rows!S13) -> TRUE
... A50: =EXACT(NEW_summary_order_items_rows!A50,'Clone (2)'!A50) -> FALSE | B50: =EXACT(NEW_summary_order_items_rows!B50,'Clone (2)'!B50) -> FALSE | C50: =EXACT(NEW_summary_order_items_rows!C50,'Clone (2)'!C50) -> FALSE | D50: =EXACT('Clone (2)'!D50,NEW_summary_order_items_rows!D50) -> FALSE | E50: =EXACT('Clone (2)'!E50,NEW_summary_order_items_rows!E50) -> FALSE | F50: =EXACT('Clone (2)'!F50,NEW_summary_order_items_rows!F50) -> FALSE | G50: =EXACT('Clone (2)'!G50,NEW_summary_order_items_rows!G50) -> FALSE | H50: =EXACT('Clone (2)'!H50,NEW_summary_order_items_rows!H50) -> FALSE | I50: =EXACT('Clone (2)'!I50,NEW_summary_order_items_rows!I50) -> FALSE | J50: =EXACT('Clone (2)'!J50,NEW_summary_order_items_rows!J50) -> TRUE | K50: =EXACT('Clone (2)'!K50,NEW_summary_order_items_rows!K50) -> FALSE | ... S50: =EXACT('Clone (2)'!S50,NEW_summary_order_items_rows!S50) -> FALSE
